[2024-01-20 11:04:19,272: INFO/MainProcess] beat: Starting...
[2024-01-21 04:00:00,011: ERROR/MainProcess] beat: Connection error: [Errno 111] Connection refused. Trying again in 2.0 seconds...
[2024-01-21 04:00:02,014: ERROR/MainProcess] beat: Connection error: [Errno 111] Connection refused. Trying again in 4.0 seconds...
[2024-01-21 04:00:06,018: ERROR/MainProcess] beat: Connection error: [Errno 111] Connection refused. Trying again in 6.0 seconds...
[2024-01-21 04:00:12,024: ERROR/MainProcess] beat: Connection error: [Errno 111] Connection refused. Trying again in 8.0 seconds...
[2024-01-21 04:00:20,032: ERROR/MainProcess] beat: Connection error: [Errno 111] Connection refused. Trying again in 10.0 seconds...
[2024-01-21 04:00:30,042: ERROR/MainProcess] beat: Connection error: [Errno 111] Connection refused. Trying again in 12.0 seconds...
[2024-01-21 04:00:42,054: ERROR/MainProcess] beat: Connection error: [Errno 111] Connection refused. Trying again in 14.0 seconds...
[2024-01-21 04:00:56,068: ERROR/MainProcess] beat: Connection error: [Errno 111] Connection refused. Trying again in 16.0 seconds...
[2024-01-21 04:01:12,084: ERROR/MainProcess] beat: Connection error: [Errno 111] Connection refused. Trying again in 18.0 seconds...
[2024-01-21 04:01:30,102: ERROR/MainProcess] beat: Connection error: [Errno 111] Connection refused. Trying again in 20.0 seconds...
[2024-01-21 04:01:50,122: ERROR/MainProcess] beat: Connection error: [Errno 111] Connection refused. Trying again in 22.0 seconds...
[2024-01-21 04:02:12,144: ERROR/MainProcess] beat: Connection error: [Errno 111] Connection refused. Trying again in 24.0 seconds...
[2024-01-21 04:02:36,168: ERROR/MainProcess] beat: Connection error: [Errno 111] Connection refused. Trying again in 26.0 seconds...
[2024-01-21 04:03:02,194: ERROR/MainProcess] beat: Connection error: [Errno 111] Connection refused. Trying again in 28.0 seconds...
[2024-01-21 04:03:30,222: ERROR/MainProcess] beat: Connection error: [Errno 111] Connection refused. Trying again in 30.0 seconds...
[2024-01-21 04:04:00,252: ERROR/MainProcess] beat: Connection error: [Errno 111] Connection refused. Trying again in 32.0 seconds...
[2024-01-21 04:04:32,284: ERROR/MainProcess] beat: Connection error: [Errno 111] Connection refused. Trying again in 32.0 seconds...
[2024-01-21 04:05:04,316: ERROR/MainProcess] beat: Connection error: [Errno 111] Connection refused. Trying again in 32.0 seconds...
[2024-01-21 04:05:36,348: ERROR/MainProcess] beat: Connection error: [Errno 111] Connection refused. Trying again in 32.0 seconds...
[2024-01-21 04:06:08,380: ERROR/MainProcess] beat: Connection error: [Errno 111] Connection refused. Trying again in 32.0 seconds...
[2024-01-21 04:06:40,412: ERROR/MainProcess] beat: Connection error: [Errno 111] Connection refused. Trying again in 32.0 seconds...
[2024-01-21 04:07:12,444: ERROR/MainProcess] beat: Connection error: [Errno 111] Connection refused. Trying again in 32.0 seconds...
[2024-01-21 04:07:44,476: ERROR/MainProcess] beat: Connection error: [Errno 111] Connection refused. Trying again in 32.0 seconds...
[2024-01-21 04:08:16,508: ERROR/MainProcess] beat: Connection error: [Errno 111] Connection refused. Trying again in 32.0 seconds...
[2024-01-21 04:08:48,540: ERROR/MainProcess] beat: Connection error: [Errno 111] Connection refused. Trying again in 32.0 seconds...
[2024-01-21 04:09:20,572: ERROR/MainProcess] beat: Connection error: [Errno 111] Connection refused. Trying again in 32.0 seconds...
[2024-01-21 04:09:52,604: ERROR/MainProcess] beat: Connection error: [Errno 111] Connection refused. Trying again in 32.0 seconds...
[2024-01-21 04:10:24,636: ERROR/MainProcess] beat: Connection error: [Errno 111] Connection refused. Trying again in 32.0 seconds...
[2024-01-21 04:10:56,702: ERROR/MainProcess] beat: Connection error: [Errno 111] Connection refused. Trying again in 32.0 seconds...
[2024-01-21 04:11:28,741: ERROR/MainProcess] beat: Connection error: [Errno 111] Connection refused. Trying again in 32.0 seconds...
[2024-01-21 04:12:00,773: ERROR/MainProcess] beat: Connection error: [Errno 111] Connection refused. Trying again in 32.0 seconds...
[2024-01-21 04:12:32,805: ERROR/MainProcess] beat: Connection error: [Errno 111] Connection refused. Trying again in 32.0 seconds...
[2024-01-21 04:13:04,837: ERROR/MainProcess] beat: Connection error: [Errno 111] Connection refused. Trying again in 32.0 seconds...
[2024-01-21 04:13:36,883: ERROR/MainProcess] beat: Connection error: [Errno 111] Connection refused. Trying again in 32.0 seconds...
[2024-01-21 04:14:08,915: ERROR/MainProcess] beat: Connection error: [Errno 111] Connection refused. Trying again in 32.0 seconds...
[2024-01-21 04:14:40,947: ERROR/MainProcess] beat: Connection error: [Errno 111] Connection refused. Trying again in 32.0 seconds...
[2024-01-21 04:15:12,979: ERROR/MainProcess] beat: Connection error: [Errno 111] Connection refused. Trying again in 32.0 seconds...
[2024-01-21 04:15:45,011: ERROR/MainProcess] beat: Connection error: [Errno 111] Connection refused. Trying again in 32.0 seconds...
[2024-01-21 04:16:17,043: ERROR/MainProcess] beat: Connection error: [Errno 111] Connection refused. Trying again in 32.0 seconds...
[2024-01-21 04:16:49,075: ERROR/MainProcess] beat: Connection error: [Errno 111] Connection refused. Trying again in 32.0 seconds...
[2024-01-21 04:17:21,107: ERROR/MainProcess] beat: Connection error: [Errno 111] Connection refused. Trying again in 32.0 seconds...
[2024-01-21 04:17:53,139: ERROR/MainProcess] beat: Connection error: [Errno 111] Connection refused. Trying again in 32.0 seconds...
[2024-01-21 04:18:25,171: ERROR/MainProcess] beat: Connection error: [Errno 111] Connection refused. Trying again in 32.0 seconds...
[2024-01-21 04:18:57,203: ERROR/MainProcess] beat: Connection error: [Errno 111] Connection refused. Trying again in 32.0 seconds...
[2024-01-21 04:19:29,235: ERROR/MainProcess] beat: Connection error: [Errno 111] Connection refused. Trying again in 32.0 seconds...
[2024-01-21 04:20:01,267: ERROR/MainProcess] beat: Connection error: [Errno 111] Connection refused. Trying again in 32.0 seconds...
[2024-01-21 04:20:33,299: ERROR/MainProcess] beat: Connection error: [Errno 111] Connection refused. Trying again in 32.0 seconds...
[2024-01-21 04:21:05,331: ERROR/MainProcess] beat: Connection error: [Errno 111] Connection refused. Trying again in 32.0 seconds...
[2024-01-21 04:21:37,363: ERROR/MainProcess] beat: Connection error: [Errno 111] Connection refused. Trying again in 32.0 seconds...
[2024-01-21 04:22:09,395: ERROR/MainProcess] beat: Connection error: [Errno 111] Connection refused. Trying again in 32.0 seconds...
[2024-01-21 04:22:41,427: ERROR/MainProcess] beat: Connection error: [Errno 111] Connection refused. Trying again in 32.0 seconds...
[2024-01-21 04:23:13,459: ERROR/MainProcess] beat: Connection error: [Errno 111] Connection refused. Trying again in 32.0 seconds...
[2024-01-21 04:23:45,491: ERROR/MainProcess] beat: Connection error: [Errno 111] Connection refused. Trying again in 32.0 seconds...
[2024-01-21 04:24:17,523: ERROR/MainProcess] beat: Connection error: [Errno 111] Connection refused. Trying again in 32.0 seconds...
[2024-01-21 04:24:49,555: ERROR/MainProcess] beat: Connection error: [Errno 111] Connection refused. Trying again in 32.0 seconds...
[2024-01-21 04:25:21,587: ERROR/MainProcess] beat: Connection error: [Errno 111] Connection refused. Trying again in 32.0 seconds...
[2024-01-21 04:25:53,619: ERROR/MainProcess] beat: Connection error: [Errno 111] Connection refused. Trying again in 32.0 seconds...
[2024-01-21 04:26:25,651: ERROR/MainProcess] beat: Connection error: [Errno 111] Connection refused. Trying again in 32.0 seconds...
[2024-01-21 04:26:57,683: ERROR/MainProcess] beat: Connection error: [Errno 111] Connection refused. Trying again in 32.0 seconds...
[2024-01-21 04:27:29,715: ERROR/MainProcess] beat: Connection error: [Errno 111] Connection refused. Trying again in 32.0 seconds...
[2024-01-21 04:28:01,747: ERROR/MainProcess] beat: Connection error: [Errno 111] Connection refused. Trying again in 32.0 seconds...
[2024-01-21 04:28:33,779: ERROR/MainProcess] beat: Connection error: [Errno 111] Connection refused. Trying again in 32.0 seconds...
[2024-01-21 04:29:05,811: ERROR/MainProcess] beat: Connection error: [Errno 111] Connection refused. Trying again in 32.0 seconds...
[2024-01-21 04:29:37,843: ERROR/MainProcess] beat: Connection error: [Errno 111] Connection refused. Trying again in 32.0 seconds...
[2024-01-21 04:30:09,875: ERROR/MainProcess] beat: Connection error: [Errno 111] Connection refused. Trying again in 32.0 seconds...
[2024-01-21 04:30:41,907: ERROR/MainProcess] beat: Connection error: [Errno 111] Connection refused. Trying again in 32.0 seconds...
[2024-01-21 04:31:13,939: ERROR/MainProcess] beat: Connection error: [Errno 111] Connection refused. Trying again in 32.0 seconds...
[2024-01-21 04:31:45,971: ERROR/MainProcess] beat: Connection error: [Errno 111] Connection refused. Trying again in 32.0 seconds...
[2024-01-21 04:32:18,003: ERROR/MainProcess] beat: Connection error: [Errno 111] Connection refused. Trying again in 32.0 seconds...
[2024-01-21 04:32:50,035: ERROR/MainProcess] beat: Connection error: [Errno 111] Connection refused. Trying again in 32.0 seconds...
[2024-01-21 04:33:22,067: ERROR/MainProcess] beat: Connection error: [Errno 111] Connection refused. Trying again in 32.0 seconds...
[2024-01-21 04:33:54,099: ERROR/MainProcess] beat: Connection error: [Errno 111] Connection refused. Trying again in 32.0 seconds...
[2024-01-21 04:34:26,131: ERROR/MainProcess] beat: Connection error: [Errno 111] Connection refused. Trying again in 32.0 seconds...
[2024-01-21 04:34:58,163: ERROR/MainProcess] beat: Connection error: [Errno 111] Connection refused. Trying again in 32.0 seconds...
[2024-01-21 04:35:30,195: ERROR/MainProcess] beat: Connection error: [Errno 111] Connection refused. Trying again in 32.0 seconds...
[2024-01-21 04:36:02,227: ERROR/MainProcess] beat: Connection error: [Errno 111] Connection refused. Trying again in 32.0 seconds...
[2024-01-21 04:36:34,259: ERROR/MainProcess] beat: Connection error: [Errno 111] Connection refused. Trying again in 32.0 seconds...
[2024-01-21 04:37:06,291: ERROR/MainProcess] beat: Connection error: [Errno 111] Connection refused. Trying again in 32.0 seconds...
[2024-01-21 04:37:38,323: ERROR/MainProcess] beat: Connection error: [Errno 111] Connection refused. Trying again in 32.0 seconds...
[2024-01-21 04:38:10,355: ERROR/MainProcess] beat: Connection error: [Errno 111] Connection refused. Trying again in 32.0 seconds...
[2024-01-21 04:38:42,387: ERROR/MainProcess] beat: Connection error: [Errno 111] Connection refused. Trying again in 32.0 seconds...
[2024-01-21 04:39:14,419: ERROR/MainProcess] beat: Connection error: [Errno 111] Connection refused. Trying again in 32.0 seconds...
[2024-01-21 04:39:46,451: ERROR/MainProcess] beat: Connection error: [Errno 111] Connection refused. Trying again in 32.0 seconds...
[2024-01-21 04:40:18,483: ERROR/MainProcess] beat: Connection error: [Errno 111] Connection refused. Trying again in 32.0 seconds...
[2024-01-21 04:40:50,515: ERROR/MainProcess] beat: Connection error: [Errno 111] Connection refused. Trying again in 32.0 seconds...
[2024-01-21 04:41:22,547: ERROR/MainProcess] beat: Connection error: [Errno 111] Connection refused. Trying again in 32.0 seconds...
[2024-01-21 04:41:54,579: ERROR/MainProcess] beat: Connection error: [Errno 111] Connection refused. Trying again in 32.0 seconds...
[2024-01-21 04:42:26,611: ERROR/MainProcess] beat: Connection error: [Errno 111] Connection refused. Trying again in 32.0 seconds...
[2024-01-21 04:42:58,643: ERROR/MainProcess] beat: Connection error: [Errno 111] Connection refused. Trying again in 32.0 seconds...
[2024-01-21 04:43:30,675: ERROR/MainProcess] beat: Connection error: [Errno 111] Connection refused. Trying again in 32.0 seconds...
[2024-01-21 04:44:02,707: ERROR/MainProcess] beat: Connection error: [Errno 111] Connection refused. Trying again in 32.0 seconds...
[2024-01-21 04:44:34,739: ERROR/MainProcess] beat: Connection error: [Errno 111] Connection refused. Trying again in 32.0 seconds...
[2024-01-21 04:45:06,771: ERROR/MainProcess] beat: Connection error: [Errno 111] Connection refused. Trying again in 32.0 seconds...
[2024-01-21 04:45:38,803: ERROR/MainProcess] beat: Connection error: [Errno 111] Connection refused. Trying again in 32.0 seconds...
[2024-01-21 04:46:10,835: ERROR/MainProcess] beat: Connection error: [Errno 111] Connection refused. Trying again in 32.0 seconds...
[2024-01-21 04:46:42,867: ERROR/MainProcess] beat: Connection error: [Errno 111] Connection refused. Trying again in 32.0 seconds...
[2024-01-21 04:47:14,899: ERROR/MainProcess] beat: Connection error: [Errno 111] Connection refused. Trying again in 32.0 seconds...
[2024-01-21 04:47:46,931: ERROR/MainProcess] beat: Connection error: [Errno 111] Connection refused. Trying again in 32.0 seconds...
[2024-01-21 04:48:18,963: ERROR/MainProcess] beat: Connection error: [Errno 111] Connection refused. Trying again in 32.0 seconds...
[2024-01-21 04:48:50,995: ERROR/MainProcess] beat: Connection error: [Errno 111] Connection refused. Trying again in 32.0 seconds...
[2024-01-21 04:49:23,292: CRITICAL/MainProcess] beat raised exception <class 'kombu.exceptions.OperationalError'>: OperationalError('[Errno 111] Connection refused')
Traceback (most recent call last):
  File "/home/yxguo/html/PokeVA/virtualenv/lib/python3.9/site-packages/kombu/connection.py", line 472, in _reraise_as_library_errors
    yield
  File "/home/yxguo/html/PokeVA/virtualenv/lib/python3.9/site-packages/kombu/connection.py", line 459, in _ensure_connection
    return retry_over_time(
  File "/home/yxguo/html/PokeVA/virtualenv/lib/python3.9/site-packages/kombu/utils/functional.py", line 318, in retry_over_time
    return fun(*args, **kwargs)
  File "/home/yxguo/html/PokeVA/virtualenv/lib/python3.9/site-packages/kombu/connection.py", line 934, in _connection_factory
    self._connection = self._establish_connection()
  File "/home/yxguo/html/PokeVA/virtualenv/lib/python3.9/site-packages/kombu/connection.py", line 860, in _establish_connection
    conn = self.transport.establish_connection()
  File "/home/yxguo/html/PokeVA/virtualenv/lib/python3.9/site-packages/kombu/transport/pyamqp.py", line 203, in establish_connection
    conn.connect()
  File "/home/yxguo/html/PokeVA/virtualenv/lib/python3.9/site-packages/amqp/connection.py", line 324, in connect
    self.transport.connect()
  File "/home/yxguo/html/PokeVA/virtualenv/lib/python3.9/site-packages/amqp/transport.py", line 129, in connect
    self._connect(self.host, self.port, self.connect_timeout)
  File "/home/yxguo/html/PokeVA/virtualenv/lib/python3.9/site-packages/amqp/transport.py", line 184, in _connect
    self.sock.connect(sa)
ConnectionRefusedError: [Errno 111] Connection refused

The above exception was the direct cause of the following exception:

Traceback (most recent call last):
  File "/home/yxguo/html/PokeVA/virtualenv/lib/python3.9/site-packages/celery/apps/beat.py", line 113, in start_scheduler
    service.start()
  File "/home/yxguo/html/PokeVA/virtualenv/lib/python3.9/site-packages/celery/beat.py", line 643, in start
    interval = self.scheduler.tick()
  File "/home/yxguo/html/PokeVA/virtualenv/lib/python3.9/site-packages/celery/beat.py", line 353, in tick
    self.apply_entry(entry, producer=self.producer)
  File "/home/yxguo/html/PokeVA/virtualenv/lib/python3.9/site-packages/kombu/utils/objects.py", line 40, in __get__
    return super().__get__(instance, owner)
  File "/home/yxguo/opt/lib/python3.9/functools.py", line 969, in __get__
    val = self.func(instance)
  File "/home/yxguo/html/PokeVA/virtualenv/lib/python3.9/site-packages/celery/beat.py", line 496, in producer
    return self.Producer(self._ensure_connected(), auto_declare=False)
  File "/home/yxguo/html/PokeVA/virtualenv/lib/python3.9/site-packages/celery/beat.py", line 479, in _ensure_connected
    return self.connection.ensure_connection(
  File "/home/yxguo/html/PokeVA/virtualenv/lib/python3.9/site-packages/kombu/connection.py", line 406, in ensure_connection
    self._ensure_connection(*args, **kwargs)
  File "/home/yxguo/html/PokeVA/virtualenv/lib/python3.9/site-packages/kombu/connection.py", line 459, in _ensure_connection
    return retry_over_time(
  File "/home/yxguo/opt/lib/python3.9/contextlib.py", line 135, in __exit__
    self.gen.throw(type, value, traceback)
  File "/home/yxguo/html/PokeVA/virtualenv/lib/python3.9/site-packages/kombu/connection.py", line 476, in _reraise_as_library_errors
    raise ConnectionError(str(exc)) from exc
kombu.exceptions.OperationalError: [Errno 111] Connection refused
[2024-01-21 04:49:23,643: WARNING/MainProcess] Traceback (most recent call last):
[2024-01-21 04:49:23,644: WARNING/MainProcess]   File "/home/yxguo/html/PokeVA/virtualenv/lib/python3.9/site-packages/kombu/connection.py", line 472, in _reraise_as_library_errors
[2024-01-21 04:49:23,644: WARNING/MainProcess]     
[2024-01-21 04:49:23,644: WARNING/MainProcess] yield
[2024-01-21 04:49:23,644: WARNING/MainProcess]   File "/home/yxguo/html/PokeVA/virtualenv/lib/python3.9/site-packages/kombu/connection.py", line 459, in _ensure_connection
[2024-01-21 04:49:23,644: WARNING/MainProcess]     
[2024-01-21 04:49:23,644: WARNING/MainProcess] return retry_over_time(
[2024-01-21 04:49:23,644: WARNING/MainProcess]   File "/home/yxguo/html/PokeVA/virtualenv/lib/python3.9/site-packages/kombu/utils/functional.py", line 318, in retry_over_time
[2024-01-21 04:49:23,644: WARNING/MainProcess]     
[2024-01-21 04:49:23,644: WARNING/MainProcess] return fun(*args, **kwargs)
[2024-01-21 04:49:23,644: WARNING/MainProcess]   File "/home/yxguo/html/PokeVA/virtualenv/lib/python3.9/site-packages/kombu/connection.py", line 934, in _connection_factory
[2024-01-21 04:49:23,645: WARNING/MainProcess]     
[2024-01-21 04:49:23,645: WARNING/MainProcess] self._connection = self._establish_connection()
[2024-01-21 04:49:23,645: WARNING/MainProcess]   File "/home/yxguo/html/PokeVA/virtualenv/lib/python3.9/site-packages/kombu/connection.py", line 860, in _establish_connection
[2024-01-21 04:49:23,645: WARNING/MainProcess]     
[2024-01-21 04:49:23,645: WARNING/MainProcess] conn = self.transport.establish_connection()
[2024-01-21 04:49:23,645: WARNING/MainProcess]   File "/home/yxguo/html/PokeVA/virtualenv/lib/python3.9/site-packages/kombu/transport/pyamqp.py", line 203, in establish_connection
[2024-01-21 04:49:23,645: WARNING/MainProcess]     
[2024-01-21 04:49:23,645: WARNING/MainProcess] conn.connect()
[2024-01-21 04:49:23,645: WARNING/MainProcess]   File "/home/yxguo/html/PokeVA/virtualenv/lib/python3.9/site-packages/amqp/connection.py", line 324, in connect
[2024-01-21 04:49:23,645: WARNING/MainProcess]     
[2024-01-21 04:49:23,645: WARNING/MainProcess] self.transport.connect()
[2024-01-21 04:49:23,645: WARNING/MainProcess]   File "/home/yxguo/html/PokeVA/virtualenv/lib/python3.9/site-packages/amqp/transport.py", line 129, in connect
[2024-01-21 04:49:23,645: WARNING/MainProcess]     
[2024-01-21 04:49:23,645: WARNING/MainProcess] self._connect(self.host, self.port, self.connect_timeout)
[2024-01-21 04:49:23,645: WARNING/MainProcess]   File "/home/yxguo/html/PokeVA/virtualenv/lib/python3.9/site-packages/amqp/transport.py", line 184, in _connect
[2024-01-21 04:49:23,646: WARNING/MainProcess]     
[2024-01-21 04:49:23,646: WARNING/MainProcess] self.sock.connect(sa)
[2024-01-21 04:49:23,646: WARNING/MainProcess] ConnectionRefusedError
[2024-01-21 04:49:23,646: WARNING/MainProcess] : 
[2024-01-21 04:49:23,646: WARNING/MainProcess] [Errno 111] Connection refused
[2024-01-21 04:49:23,646: WARNING/MainProcess] 
The above exception was the direct cause of the following exception:
[2024-01-21 04:49:23,646: WARNING/MainProcess] Traceback (most recent call last):
[2024-01-21 04:49:23,646: WARNING/MainProcess]   File "/home/yxguo/html/PokeVA/virtualenv/bin/celery", line 8, in <module>
[2024-01-21 04:49:23,646: WARNING/MainProcess]     
[2024-01-21 04:49:23,646: WARNING/MainProcess] sys.exit(main())
[2024-01-21 04:49:23,646: WARNING/MainProcess]   File "/home/yxguo/html/PokeVA/virtualenv/lib/python3.9/site-packages/celery/__main__.py", line 15, in main
[2024-01-21 04:49:23,646: WARNING/MainProcess]     
[2024-01-21 04:49:23,646: WARNING/MainProcess] sys.exit(_main())
[2024-01-21 04:49:23,646: WARNING/MainProcess]   File "/home/yxguo/html/PokeVA/virtualenv/lib/python3.9/site-packages/celery/bin/celery.py", line 236, in main
[2024-01-21 04:49:23,646: WARNING/MainProcess]     
[2024-01-21 04:49:23,646: WARNING/MainProcess] return celery(auto_envvar_prefix="CELERY")
[2024-01-21 04:49:23,646: WARNING/MainProcess]   File "/home/yxguo/html/PokeVA/virtualenv/lib/python3.9/site-packages/click/core.py", line 1157, in __call__
[2024-01-21 04:49:23,647: WARNING/MainProcess]     
[2024-01-21 04:49:23,647: WARNING/MainProcess] return self.main(*args, **kwargs)
[2024-01-21 04:49:23,647: WARNING/MainProcess]   File "/home/yxguo/html/PokeVA/virtualenv/lib/python3.9/site-packages/click/core.py", line 1078, in main
[2024-01-21 04:49:23,647: WARNING/MainProcess]     
[2024-01-21 04:49:23,647: WARNING/MainProcess] rv = self.invoke(ctx)
[2024-01-21 04:49:23,647: WARNING/MainProcess]   File "/home/yxguo/html/PokeVA/virtualenv/lib/python3.9/site-packages/click/core.py", line 1688, in invoke
[2024-01-21 04:49:23,647: WARNING/MainProcess]     
[2024-01-21 04:49:23,647: WARNING/MainProcess] return _process_result(sub_ctx.command.invoke(sub_ctx))
[2024-01-21 04:49:23,647: WARNING/MainProcess]   File "/home/yxguo/html/PokeVA/virtualenv/lib/python3.9/site-packages/click/core.py", line 1434, in invoke
[2024-01-21 04:49:23,648: WARNING/MainProcess]     
[2024-01-21 04:49:23,648: WARNING/MainProcess] return ctx.invoke(self.callback, **ctx.params)
[2024-01-21 04:49:23,648: WARNING/MainProcess]   File "/home/yxguo/html/PokeVA/virtualenv/lib/python3.9/site-packages/click/core.py", line 783, in invoke
[2024-01-21 04:49:23,648: WARNING/MainProcess]     
[2024-01-21 04:49:23,648: WARNING/MainProcess] return __callback(*args, **kwargs)
[2024-01-21 04:49:23,648: WARNING/MainProcess]   File "/home/yxguo/html/PokeVA/virtualenv/lib/python3.9/site-packages/click/decorators.py", line 33, in new_func
[2024-01-21 04:49:23,648: WARNING/MainProcess]     
[2024-01-21 04:49:23,648: WARNING/MainProcess] return f(get_current_context(), *args, **kwargs)
[2024-01-21 04:49:23,648: WARNING/MainProcess]   File "/home/yxguo/html/PokeVA/virtualenv/lib/python3.9/site-packages/celery/bin/base.py", line 134, in caller
[2024-01-21 04:49:23,648: WARNING/MainProcess]     
[2024-01-21 04:49:23,648: WARNING/MainProcess] return f(ctx, *args, **kwargs)
[2024-01-21 04:49:23,648: WARNING/MainProcess]   File "/home/yxguo/html/PokeVA/virtualenv/lib/python3.9/site-packages/celery/bin/beat.py", line 72, in beat
[2024-01-21 04:49:23,658: WARNING/MainProcess]     
[2024-01-21 04:49:23,658: WARNING/MainProcess] return beat().run()
[2024-01-21 04:49:23,658: WARNING/MainProcess]   File "/home/yxguo/html/PokeVA/virtualenv/lib/python3.9/site-packages/celery/apps/beat.py", line 84, in run
[2024-01-21 04:49:23,658: WARNING/MainProcess]     
[2024-01-21 04:49:23,658: WARNING/MainProcess] self.start_scheduler()
[2024-01-21 04:49:23,658: WARNING/MainProcess]   File "/home/yxguo/html/PokeVA/virtualenv/lib/python3.9/site-packages/celery/apps/beat.py", line 113, in start_scheduler
[2024-01-21 04:49:23,658: WARNING/MainProcess]     
[2024-01-21 04:49:23,658: WARNING/MainProcess] service.start()
[2024-01-21 04:49:23,658: WARNING/MainProcess]   File "/home/yxguo/html/PokeVA/virtualenv/lib/python3.9/site-packages/celery/beat.py", line 643, in start
[2024-01-21 04:49:23,658: WARNING/MainProcess]     
[2024-01-21 04:49:23,658: WARNING/MainProcess] interval = self.scheduler.tick()
[2024-01-21 04:49:23,658: WARNING/MainProcess]   File "/home/yxguo/html/PokeVA/virtualenv/lib/python3.9/site-packages/celery/beat.py", line 353, in tick
[2024-01-21 04:49:23,659: WARNING/MainProcess]     
[2024-01-21 04:49:23,659: WARNING/MainProcess] self.apply_entry(entry, producer=self.producer)
[2024-01-21 04:49:23,659: WARNING/MainProcess]   File "/home/yxguo/html/PokeVA/virtualenv/lib/python3.9/site-packages/kombu/utils/objects.py", line 40, in __get__
[2024-01-21 04:49:23,659: WARNING/MainProcess]     
[2024-01-21 04:49:23,659: WARNING/MainProcess] return super().__get__(instance, owner)
[2024-01-21 04:49:23,659: WARNING/MainProcess]   File "/home/yxguo/opt/lib/python3.9/functools.py", line 969, in __get__
[2024-01-21 04:49:23,659: WARNING/MainProcess]     
[2024-01-21 04:49:23,659: WARNING/MainProcess] val = self.func(instance)
[2024-01-21 04:49:23,659: WARNING/MainProcess]   File "/home/yxguo/html/PokeVA/virtualenv/lib/python3.9/site-packages/celery/beat.py", line 496, in producer
[2024-01-21 04:49:23,659: WARNING/MainProcess]     
[2024-01-21 04:49:23,659: WARNING/MainProcess] return self.Producer(self._ensure_connected(), auto_declare=False)
[2024-01-21 04:49:23,659: WARNING/MainProcess]   File "/home/yxguo/html/PokeVA/virtualenv/lib/python3.9/site-packages/celery/beat.py", line 479, in _ensure_connected
[2024-01-21 04:49:23,660: WARNING/MainProcess]     
[2024-01-21 04:49:23,660: WARNING/MainProcess] return self.connection.ensure_connection(
[2024-01-21 04:49:23,660: WARNING/MainProcess]   File "/home/yxguo/html/PokeVA/virtualenv/lib/python3.9/site-packages/kombu/connection.py", line 406, in ensure_connection
[2024-01-21 04:49:23,660: WARNING/MainProcess]     
[2024-01-21 04:49:23,660: WARNING/MainProcess] self._ensure_connection(*args, **kwargs)
[2024-01-21 04:49:23,660: WARNING/MainProcess]   File "/home/yxguo/html/PokeVA/virtualenv/lib/python3.9/site-packages/kombu/connection.py", line 459, in _ensure_connection
[2024-01-21 04:49:23,660: WARNING/MainProcess]     
[2024-01-21 04:49:23,660: WARNING/MainProcess] return retry_over_time(
[2024-01-21 04:49:23,660: WARNING/MainProcess]   File "/home/yxguo/opt/lib/python3.9/contextlib.py", line 135, in __exit__
[2024-01-21 04:49:23,660: WARNING/MainProcess]     
[2024-01-21 04:49:23,660: WARNING/MainProcess] self.gen.throw(type, value, traceback)
[2024-01-21 04:49:23,660: WARNING/MainProcess]   File "/home/yxguo/html/PokeVA/virtualenv/lib/python3.9/site-packages/kombu/connection.py", line 476, in _reraise_as_library_errors
[2024-01-21 04:49:23,660: WARNING/MainProcess]     
[2024-01-21 04:49:23,660: WARNING/MainProcess] raise ConnectionError(str(exc)) from exc
[2024-01-21 04:49:23,660: WARNING/MainProcess] kombu.exceptions
[2024-01-21 04:49:23,660: WARNING/MainProcess] .
[2024-01-21 04:49:23,661: WARNING/MainProcess] OperationalError
[2024-01-21 04:49:23,661: WARNING/MainProcess] : 
[2024-01-21 04:49:23,661: WARNING/MainProcess] [Errno 111] Connection refused
[2024-01-21 04:49:25,212: INFO/MainProcess] beat: Starting...
[2024-01-22 04:00:00,002: ERROR/MainProcess] beat: Connection error: [Errno 111] Connection refused. Trying again in 2.0 seconds...
[2024-01-22 04:00:02,004: ERROR/MainProcess] beat: Connection error: [Errno 111] Connection refused. Trying again in 4.0 seconds...
[2024-01-22 04:00:06,008: ERROR/MainProcess] beat: Connection error: [Errno 111] Connection refused. Trying again in 6.0 seconds...
[2024-01-22 04:00:12,014: ERROR/MainProcess] beat: Connection error: [Errno 111] Connection refused. Trying again in 8.0 seconds...
[2024-01-22 04:00:20,022: ERROR/MainProcess] beat: Connection error: [Errno 111] Connection refused. Trying again in 10.0 seconds...
[2024-01-22 04:00:30,112: ERROR/MainProcess] beat: Connection error: [Errno 111] Connection refused. Trying again in 12.0 seconds...
[2024-01-22 04:00:42,124: ERROR/MainProcess] beat: Connection error: [Errno 111] Connection refused. Trying again in 14.0 seconds...
[2024-01-22 04:00:56,138: ERROR/MainProcess] beat: Connection error: [Errno 111] Connection refused. Trying again in 16.0 seconds...
[2024-01-22 04:01:12,154: ERROR/MainProcess] beat: Connection error: [Errno 111] Connection refused. Trying again in 18.0 seconds...
[2024-01-22 04:01:30,172: ERROR/MainProcess] beat: Connection error: [Errno 111] Connection refused. Trying again in 20.0 seconds...
[2024-01-22 04:01:50,192: ERROR/MainProcess] beat: Connection error: [Errno 111] Connection refused. Trying again in 22.0 seconds...
[2024-01-22 04:02:12,214: ERROR/MainProcess] beat: Connection error: [Errno 111] Connection refused. Trying again in 24.0 seconds...
[2024-01-22 04:02:36,238: ERROR/MainProcess] beat: Connection error: [Errno 111] Connection refused. Trying again in 26.0 seconds...
[2024-01-22 04:03:02,264: ERROR/MainProcess] beat: Connection error: [Errno 111] Connection refused. Trying again in 28.0 seconds...
[2024-01-22 04:03:30,292: ERROR/MainProcess] beat: Connection error: [Errno 111] Connection refused. Trying again in 30.0 seconds...
[2024-01-22 04:04:00,322: ERROR/MainProcess] beat: Connection error: [Errno 111] Connection refused. Trying again in 32.0 seconds...
[2024-01-22 04:04:32,354: ERROR/MainProcess] beat: Connection error: [Errno 111] Connection refused. Trying again in 32.0 seconds...
[2024-01-22 04:05:04,386: ERROR/MainProcess] beat: Connection error: [Errno 111] Connection refused. Trying again in 32.0 seconds...
[2024-01-22 04:05:36,418: ERROR/MainProcess] beat: Connection error: [Errno 111] Connection refused. Trying again in 32.0 seconds...
[2024-01-22 04:06:08,450: ERROR/MainProcess] beat: Connection error: [Errno 111] Connection refused. Trying again in 32.0 seconds...
[2024-01-22 04:06:40,482: ERROR/MainProcess] beat: Connection error: [Errno 111] Connection refused. Trying again in 32.0 seconds...
[2024-01-22 04:07:12,514: ERROR/MainProcess] beat: Connection error: [Errno 111] Connection refused. Trying again in 32.0 seconds...
[2024-01-22 04:07:44,546: ERROR/MainProcess] beat: Connection error: [Errno 111] Connection refused. Trying again in 32.0 seconds...
[2024-01-22 04:08:16,578: ERROR/MainProcess] beat: Connection error: [Errno 111] Connection refused. Trying again in 32.0 seconds...
[2024-01-22 04:08:48,610: ERROR/MainProcess] beat: Connection error: [Errno 111] Connection refused. Trying again in 32.0 seconds...
[2024-01-22 04:09:20,642: ERROR/MainProcess] beat: Connection error: [Errno 111] Connection refused. Trying again in 32.0 seconds...
[2024-01-22 04:09:52,674: ERROR/MainProcess] beat: Connection error: [Errno 111] Connection refused. Trying again in 32.0 seconds...
[2024-01-22 04:10:24,706: ERROR/MainProcess] beat: Connection error: [Errno 111] Connection refused. Trying again in 32.0 seconds...
[2024-01-22 04:10:56,738: ERROR/MainProcess] beat: Connection error: [Errno 111] Connection refused. Trying again in 32.0 seconds...
[2024-01-22 04:11:28,770: ERROR/MainProcess] beat: Connection error: [Errno 111] Connection refused. Trying again in 32.0 seconds...
[2024-01-22 04:12:00,802: ERROR/MainProcess] beat: Connection error: [Errno 111] Connection refused. Trying again in 32.0 seconds...
[2024-01-22 04:12:32,834: ERROR/MainProcess] beat: Connection error: [Errno 111] Connection refused. Trying again in 32.0 seconds...
[2024-01-22 04:13:04,866: ERROR/MainProcess] beat: Connection error: [Errno 111] Connection refused. Trying again in 32.0 seconds...
[2024-01-22 04:13:36,898: ERROR/MainProcess] beat: Connection error: [Errno 111] Connection refused. Trying again in 32.0 seconds...
[2024-01-22 04:14:08,930: ERROR/MainProcess] beat: Connection error: [Errno 111] Connection refused. Trying again in 32.0 seconds...
[2024-01-22 04:14:40,962: ERROR/MainProcess] beat: Connection error: [Errno 111] Connection refused. Trying again in 32.0 seconds...
[2024-01-22 04:15:12,994: ERROR/MainProcess] beat: Connection error: [Errno 111] Connection refused. Trying again in 32.0 seconds...
[2024-01-22 04:15:45,026: ERROR/MainProcess] beat: Connection error: [Errno 111] Connection refused. Trying again in 32.0 seconds...
[2024-01-22 04:16:17,058: ERROR/MainProcess] beat: Connection error: [Errno 111] Connection refused. Trying again in 32.0 seconds...
[2024-01-22 04:16:49,090: ERROR/MainProcess] beat: Connection error: [Errno 111] Connection refused. Trying again in 32.0 seconds...
[2024-01-22 04:17:21,122: ERROR/MainProcess] beat: Connection error: [Errno 111] Connection refused. Trying again in 32.0 seconds...
[2024-01-22 04:17:53,154: ERROR/MainProcess] beat: Connection error: [Errno 111] Connection refused. Trying again in 32.0 seconds...
[2024-01-22 04:18:25,186: ERROR/MainProcess] beat: Connection error: [Errno 111] Connection refused. Trying again in 32.0 seconds...
[2024-01-22 04:18:57,218: ERROR/MainProcess] beat: Connection error: [Errno 111] Connection refused. Trying again in 32.0 seconds...
[2024-01-22 04:19:29,250: ERROR/MainProcess] beat: Connection error: [Errno 111] Connection refused. Trying again in 32.0 seconds...
[2024-01-22 04:20:01,282: ERROR/MainProcess] beat: Connection error: [Errno 111] Connection refused. Trying again in 32.0 seconds...
[2024-01-22 04:20:33,314: ERROR/MainProcess] beat: Connection error: [Errno 111] Connection refused. Trying again in 32.0 seconds...
[2024-01-22 04:21:05,346: ERROR/MainProcess] beat: Connection error: [Errno 111] Connection refused. Trying again in 32.0 seconds...
[2024-01-22 04:21:37,378: ERROR/MainProcess] beat: Connection error: [Errno 111] Connection refused. Trying again in 32.0 seconds...
[2024-01-22 04:22:09,410: ERROR/MainProcess] beat: Connection error: [Errno 111] Connection refused. Trying again in 32.0 seconds...
[2024-01-22 04:22:41,442: ERROR/MainProcess] beat: Connection error: [Errno 111] Connection refused. Trying again in 32.0 seconds...
[2024-01-22 04:23:13,474: ERROR/MainProcess] beat: Connection error: [Errno 111] Connection refused. Trying again in 32.0 seconds...
[2024-01-22 04:23:45,506: ERROR/MainProcess] beat: Connection error: [Errno 111] Connection refused. Trying again in 32.0 seconds...
[2024-01-22 04:24:17,538: ERROR/MainProcess] beat: Connection error: [Errno 111] Connection refused. Trying again in 32.0 seconds...
[2024-01-22 04:24:49,570: ERROR/MainProcess] beat: Connection error: [Errno 111] Connection refused. Trying again in 32.0 seconds...
[2024-01-22 04:25:21,602: ERROR/MainProcess] beat: Connection error: [Errno 111] Connection refused. Trying again in 32.0 seconds...
[2024-01-22 04:25:53,634: ERROR/MainProcess] beat: Connection error: [Errno 111] Connection refused. Trying again in 32.0 seconds...
[2024-01-22 04:26:25,666: ERROR/MainProcess] beat: Connection error: [Errno 111] Connection refused. Trying again in 32.0 seconds...
[2024-01-22 04:26:57,698: ERROR/MainProcess] beat: Connection error: [Errno 111] Connection refused. Trying again in 32.0 seconds...
[2024-01-22 04:27:29,730: ERROR/MainProcess] beat: Connection error: [Errno 111] Connection refused. Trying again in 32.0 seconds...
[2024-01-22 04:28:01,762: ERROR/MainProcess] beat: Connection error: [Errno 111] Connection refused. Trying again in 32.0 seconds...
[2024-01-22 04:28:33,794: ERROR/MainProcess] beat: Connection error: [Errno 111] Connection refused. Trying again in 32.0 seconds...
[2024-01-22 04:29:05,826: ERROR/MainProcess] beat: Connection error: [Errno 111] Connection refused. Trying again in 32.0 seconds...
[2024-01-22 04:29:37,858: ERROR/MainProcess] beat: Connection error: [Errno 111] Connection refused. Trying again in 32.0 seconds...
[2024-01-22 04:30:09,890: ERROR/MainProcess] beat: Connection error: [Errno 111] Connection refused. Trying again in 32.0 seconds...
[2024-01-22 04:30:41,922: ERROR/MainProcess] beat: Connection error: [Errno 111] Connection refused. Trying again in 32.0 seconds...
[2024-01-22 04:31:13,954: ERROR/MainProcess] beat: Connection error: [Errno 111] Connection refused. Trying again in 32.0 seconds...
[2024-01-22 04:31:45,986: ERROR/MainProcess] beat: Connection error: [Errno 111] Connection refused. Trying again in 32.0 seconds...
[2024-01-22 04:32:18,018: ERROR/MainProcess] beat: Connection error: [Errno 111] Connection refused. Trying again in 32.0 seconds...
[2024-01-22 04:32:50,050: ERROR/MainProcess] beat: Connection error: [Errno 111] Connection refused. Trying again in 32.0 seconds...
[2024-01-22 04:33:22,082: ERROR/MainProcess] beat: Connection error: [Errno 111] Connection refused. Trying again in 32.0 seconds...
[2024-01-22 04:33:54,114: ERROR/MainProcess] beat: Connection error: [Errno 111] Connection refused. Trying again in 32.0 seconds...
[2024-01-22 04:34:26,146: ERROR/MainProcess] beat: Connection error: [Errno 111] Connection refused. Trying again in 32.0 seconds...
[2024-01-22 04:34:58,178: ERROR/MainProcess] beat: Connection error: [Errno 111] Connection refused. Trying again in 32.0 seconds...
[2024-01-22 04:35:30,210: ERROR/MainProcess] beat: Connection error: [Errno 111] Connection refused. Trying again in 32.0 seconds...
[2024-01-22 04:36:02,242: ERROR/MainProcess] beat: Connection error: [Errno 111] Connection refused. Trying again in 32.0 seconds...
[2024-01-22 04:36:34,274: ERROR/MainProcess] beat: Connection error: [Errno 111] Connection refused. Trying again in 32.0 seconds...
[2024-01-22 04:37:06,306: ERROR/MainProcess] beat: Connection error: [Errno 111] Connection refused. Trying again in 32.0 seconds...
[2024-01-22 04:37:38,338: ERROR/MainProcess] beat: Connection error: [Errno 111] Connection refused. Trying again in 32.0 seconds...
[2024-01-22 04:38:10,370: ERROR/MainProcess] beat: Connection error: [Errno 111] Connection refused. Trying again in 32.0 seconds...
[2024-01-22 04:38:42,402: ERROR/MainProcess] beat: Connection error: [Errno 111] Connection refused. Trying again in 32.0 seconds...
[2024-01-22 04:39:14,434: ERROR/MainProcess] beat: Connection error: [Errno 111] Connection refused. Trying again in 32.0 seconds...
[2024-01-22 04:39:46,466: ERROR/MainProcess] beat: Connection error: [Errno 111] Connection refused. Trying again in 32.0 seconds...
[2024-01-22 04:40:18,498: ERROR/MainProcess] beat: Connection error: [Errno 111] Connection refused. Trying again in 32.0 seconds...
[2024-01-22 04:40:50,530: ERROR/MainProcess] beat: Connection error: [Errno 111] Connection refused. Trying again in 32.0 seconds...
[2024-01-22 04:41:22,562: ERROR/MainProcess] beat: Connection error: [Errno 111] Connection refused. Trying again in 32.0 seconds...
[2024-01-22 04:41:54,594: ERROR/MainProcess] beat: Connection error: [Errno 111] Connection refused. Trying again in 32.0 seconds...
[2024-01-22 04:42:26,626: ERROR/MainProcess] beat: Connection error: [Errno 111] Connection refused. Trying again in 32.0 seconds...
[2024-01-22 04:42:58,658: ERROR/MainProcess] beat: Connection error: [Errno 111] Connection refused. Trying again in 32.0 seconds...
[2024-01-22 04:43:30,690: ERROR/MainProcess] beat: Connection error: [Errno 111] Connection refused. Trying again in 32.0 seconds...
[2024-01-22 04:44:02,722: ERROR/MainProcess] beat: Connection error: [Errno 111] Connection refused. Trying again in 32.0 seconds...
[2024-01-22 04:44:34,754: ERROR/MainProcess] beat: Connection error: [Errno 111] Connection refused. Trying again in 32.0 seconds...
[2024-01-22 04:45:06,786: ERROR/MainProcess] beat: Connection error: [Errno 111] Connection refused. Trying again in 32.0 seconds...
[2024-01-22 04:45:38,818: ERROR/MainProcess] beat: Connection error: [Errno 111] Connection refused. Trying again in 32.0 seconds...
[2024-01-22 04:46:10,850: ERROR/MainProcess] beat: Connection error: [Errno 111] Connection refused. Trying again in 32.0 seconds...
[2024-01-22 04:46:42,882: ERROR/MainProcess] beat: Connection error: [Errno 111] Connection refused. Trying again in 32.0 seconds...
[2024-01-22 04:47:14,914: ERROR/MainProcess] beat: Connection error: [Errno 111] Connection refused. Trying again in 32.0 seconds...
[2024-01-22 04:47:46,946: ERROR/MainProcess] beat: Connection error: [Errno 111] Connection refused. Trying again in 32.0 seconds...
[2024-01-22 04:48:18,978: ERROR/MainProcess] beat: Connection error: [Errno 111] Connection refused. Trying again in 32.0 seconds...
[2024-01-22 04:48:51,010: ERROR/MainProcess] beat: Connection error: [Errno 111] Connection refused. Trying again in 32.0 seconds...
[2024-01-22 04:49:23,043: CRITICAL/MainProcess] beat raised exception <class 'kombu.exceptions.OperationalError'>: OperationalError('[Errno 111] Connection refused')
Traceback (most recent call last):
  File "/home/yxguo/html/PokeVA/virtualenv/lib/python3.9/site-packages/kombu/connection.py", line 472, in _reraise_as_library_errors
    yield
  File "/home/yxguo/html/PokeVA/virtualenv/lib/python3.9/site-packages/kombu/connection.py", line 459, in _ensure_connection
    return retry_over_time(
  File "/home/yxguo/html/PokeVA/virtualenv/lib/python3.9/site-packages/kombu/utils/functional.py", line 318, in retry_over_time
    return fun(*args, **kwargs)
  File "/home/yxguo/html/PokeVA/virtualenv/lib/python3.9/site-packages/kombu/connection.py", line 934, in _connection_factory
    self._connection = self._establish_connection()
  File "/home/yxguo/html/PokeVA/virtualenv/lib/python3.9/site-packages/kombu/connection.py", line 860, in _establish_connection
    conn = self.transport.establish_connection()
  File "/home/yxguo/html/PokeVA/virtualenv/lib/python3.9/site-packages/kombu/transport/pyamqp.py", line 203, in establish_connection
    conn.connect()
  File "/home/yxguo/html/PokeVA/virtualenv/lib/python3.9/site-packages/amqp/connection.py", line 324, in connect
    self.transport.connect()
  File "/home/yxguo/html/PokeVA/virtualenv/lib/python3.9/site-packages/amqp/transport.py", line 129, in connect
    self._connect(self.host, self.port, self.connect_timeout)
  File "/home/yxguo/html/PokeVA/virtualenv/lib/python3.9/site-packages/amqp/transport.py", line 184, in _connect
    self.sock.connect(sa)
ConnectionRefusedError: [Errno 111] Connection refused

The above exception was the direct cause of the following exception:

Traceback (most recent call last):
  File "/home/yxguo/html/PokeVA/virtualenv/lib/python3.9/site-packages/celery/apps/beat.py", line 113, in start_scheduler
    service.start()
  File "/home/yxguo/html/PokeVA/virtualenv/lib/python3.9/site-packages/celery/beat.py", line 643, in start
    interval = self.scheduler.tick()
  File "/home/yxguo/html/PokeVA/virtualenv/lib/python3.9/site-packages/celery/beat.py", line 353, in tick
    self.apply_entry(entry, producer=self.producer)
  File "/home/yxguo/html/PokeVA/virtualenv/lib/python3.9/site-packages/kombu/utils/objects.py", line 40, in __get__
    return super().__get__(instance, owner)
  File "/home/yxguo/opt/lib/python3.9/functools.py", line 969, in __get__
    val = self.func(instance)
  File "/home/yxguo/html/PokeVA/virtualenv/lib/python3.9/site-packages/celery/beat.py", line 496, in producer
    return self.Producer(self._ensure_connected(), auto_declare=False)
  File "/home/yxguo/html/PokeVA/virtualenv/lib/python3.9/site-packages/celery/beat.py", line 479, in _ensure_connected
    return self.connection.ensure_connection(
  File "/home/yxguo/html/PokeVA/virtualenv/lib/python3.9/site-packages/kombu/connection.py", line 406, in ensure_connection
    self._ensure_connection(*args, **kwargs)
  File "/home/yxguo/html/PokeVA/virtualenv/lib/python3.9/site-packages/kombu/connection.py", line 459, in _ensure_connection
    return retry_over_time(
  File "/home/yxguo/opt/lib/python3.9/contextlib.py", line 135, in __exit__
    self.gen.throw(type, value, traceback)
  File "/home/yxguo/html/PokeVA/virtualenv/lib/python3.9/site-packages/kombu/connection.py", line 476, in _reraise_as_library_errors
    raise ConnectionError(str(exc)) from exc
kombu.exceptions.OperationalError: [Errno 111] Connection refused
[2024-01-22 04:49:23,092: WARNING/MainProcess] Traceback (most recent call last):
[2024-01-22 04:49:23,092: WARNING/MainProcess]   File "/home/yxguo/html/PokeVA/virtualenv/lib/python3.9/site-packages/kombu/connection.py", line 472, in _reraise_as_library_errors
[2024-01-22 04:49:23,093: WARNING/MainProcess]     
[2024-01-22 04:49:23,093: WARNING/MainProcess] yield
[2024-01-22 04:49:23,093: WARNING/MainProcess]   File "/home/yxguo/html/PokeVA/virtualenv/lib/python3.9/site-packages/kombu/connection.py", line 459, in _ensure_connection
[2024-01-22 04:49:23,093: WARNING/MainProcess]     
[2024-01-22 04:49:23,093: WARNING/MainProcess] return retry_over_time(
[2024-01-22 04:49:23,093: WARNING/MainProcess]   File "/home/yxguo/html/PokeVA/virtualenv/lib/python3.9/site-packages/kombu/utils/functional.py", line 318, in retry_over_time
[2024-01-22 04:49:23,093: WARNING/MainProcess]     
[2024-01-22 04:49:23,093: WARNING/MainProcess] return fun(*args, **kwargs)
[2024-01-22 04:49:23,093: WARNING/MainProcess]   File "/home/yxguo/html/PokeVA/virtualenv/lib/python3.9/site-packages/kombu/connection.py", line 934, in _connection_factory
[2024-01-22 04:49:23,093: WARNING/MainProcess]     
[2024-01-22 04:49:23,093: WARNING/MainProcess] self._connection = self._establish_connection()
[2024-01-22 04:49:23,093: WARNING/MainProcess]   File "/home/yxguo/html/PokeVA/virtualenv/lib/python3.9/site-packages/kombu/connection.py", line 860, in _establish_connection
[2024-01-22 04:49:23,094: WARNING/MainProcess]     
[2024-01-22 04:49:23,094: WARNING/MainProcess] conn = self.transport.establish_connection()
[2024-01-22 04:49:23,094: WARNING/MainProcess]   File "/home/yxguo/html/PokeVA/virtualenv/lib/python3.9/site-packages/kombu/transport/pyamqp.py", line 203, in establish_connection
[2024-01-22 04:49:23,094: WARNING/MainProcess]     
[2024-01-22 04:49:23,094: WARNING/MainProcess] conn.connect()
[2024-01-22 04:49:23,094: WARNING/MainProcess]   File "/home/yxguo/html/PokeVA/virtualenv/lib/python3.9/site-packages/amqp/connection.py", line 324, in connect
[2024-01-22 04:49:23,094: WARNING/MainProcess]     
[2024-01-22 04:49:23,094: WARNING/MainProcess] self.transport.connect()
[2024-01-22 04:49:23,094: WARNING/MainProcess]   File "/home/yxguo/html/PokeVA/virtualenv/lib/python3.9/site-packages/amqp/transport.py", line 129, in connect
[2024-01-22 04:49:23,094: WARNING/MainProcess]     
[2024-01-22 04:49:23,094: WARNING/MainProcess] self._connect(self.host, self.port, self.connect_timeout)
[2024-01-22 04:49:23,094: WARNING/MainProcess]   File "/home/yxguo/html/PokeVA/virtualenv/lib/python3.9/site-packages/amqp/transport.py", line 184, in _connect
[2024-01-22 04:49:23,094: WARNING/MainProcess]     
[2024-01-22 04:49:23,094: WARNING/MainProcess] self.sock.connect(sa)
[2024-01-22 04:49:23,094: WARNING/MainProcess] ConnectionRefusedError
[2024-01-22 04:49:23,094: WARNING/MainProcess] : 
[2024-01-22 04:49:23,094: WARNING/MainProcess] [Errno 111] Connection refused
[2024-01-22 04:49:23,095: WARNING/MainProcess] 
The above exception was the direct cause of the following exception:
[2024-01-22 04:49:23,095: WARNING/MainProcess] Traceback (most recent call last):
[2024-01-22 04:49:23,095: WARNING/MainProcess]   File "/home/yxguo/html/PokeVA/virtualenv/bin/celery", line 8, in <module>
[2024-01-22 04:49:23,095: WARNING/MainProcess]     
[2024-01-22 04:49:23,095: WARNING/MainProcess] sys.exit(main())
[2024-01-22 04:49:23,095: WARNING/MainProcess]   File "/home/yxguo/html/PokeVA/virtualenv/lib/python3.9/site-packages/celery/__main__.py", line 15, in main
[2024-01-22 04:49:23,095: WARNING/MainProcess]     
[2024-01-22 04:49:23,095: WARNING/MainProcess] sys.exit(_main())
[2024-01-22 04:49:23,095: WARNING/MainProcess]   File "/home/yxguo/html/PokeVA/virtualenv/lib/python3.9/site-packages/celery/bin/celery.py", line 236, in main
[2024-01-22 04:49:23,095: WARNING/MainProcess]     
[2024-01-22 04:49:23,095: WARNING/MainProcess] return celery(auto_envvar_prefix="CELERY")
[2024-01-22 04:49:23,095: WARNING/MainProcess]   File "/home/yxguo/html/PokeVA/virtualenv/lib/python3.9/site-packages/click/core.py", line 1157, in __call__
[2024-01-22 04:49:23,095: WARNING/MainProcess]     
[2024-01-22 04:49:23,095: WARNING/MainProcess] return self.main(*args, **kwargs)
[2024-01-22 04:49:23,095: WARNING/MainProcess]   File "/home/yxguo/html/PokeVA/virtualenv/lib/python3.9/site-packages/click/core.py", line 1078, in main
[2024-01-22 04:49:23,096: WARNING/MainProcess]     
[2024-01-22 04:49:23,096: WARNING/MainProcess] rv = self.invoke(ctx)
[2024-01-22 04:49:23,096: WARNING/MainProcess]   File "/home/yxguo/html/PokeVA/virtualenv/lib/python3.9/site-packages/click/core.py", line 1688, in invoke
[2024-01-22 04:49:23,096: WARNING/MainProcess]     
[2024-01-22 04:49:23,096: WARNING/MainProcess] return _process_result(sub_ctx.command.invoke(sub_ctx))
[2024-01-22 04:49:23,096: WARNING/MainProcess]   File "/home/yxguo/html/PokeVA/virtualenv/lib/python3.9/site-packages/click/core.py", line 1434, in invoke
[2024-01-22 04:49:23,096: WARNING/MainProcess]     
[2024-01-22 04:49:23,096: WARNING/MainProcess] return ctx.invoke(self.callback, **ctx.params)
[2024-01-22 04:49:23,096: WARNING/MainProcess]   File "/home/yxguo/html/PokeVA/virtualenv/lib/python3.9/site-packages/click/core.py", line 783, in invoke
[2024-01-22 04:49:23,097: WARNING/MainProcess]     
[2024-01-22 04:49:23,097: WARNING/MainProcess] return __callback(*args, **kwargs)
[2024-01-22 04:49:23,097: WARNING/MainProcess]   File "/home/yxguo/html/PokeVA/virtualenv/lib/python3.9/site-packages/click/decorators.py", line 33, in new_func
[2024-01-22 04:49:23,097: WARNING/MainProcess]     
[2024-01-22 04:49:23,097: WARNING/MainProcess] return f(get_current_context(), *args, **kwargs)
[2024-01-22 04:49:23,097: WARNING/MainProcess]   File "/home/yxguo/html/PokeVA/virtualenv/lib/python3.9/site-packages/celery/bin/base.py", line 134, in caller
[2024-01-22 04:49:23,097: WARNING/MainProcess]     
[2024-01-22 04:49:23,097: WARNING/MainProcess] return f(ctx, *args, **kwargs)
[2024-01-22 04:49:23,097: WARNING/MainProcess]   File "/home/yxguo/html/PokeVA/virtualenv/lib/python3.9/site-packages/celery/bin/beat.py", line 72, in beat
[2024-01-22 04:49:23,097: WARNING/MainProcess]     
[2024-01-22 04:49:23,097: WARNING/MainProcess] return beat().run()
[2024-01-22 04:49:23,097: WARNING/MainProcess]   File "/home/yxguo/html/PokeVA/virtualenv/lib/python3.9/site-packages/celery/apps/beat.py", line 84, in run
[2024-01-22 04:49:23,097: WARNING/MainProcess]     
[2024-01-22 04:49:23,097: WARNING/MainProcess] self.start_scheduler()
[2024-01-22 04:49:23,097: WARNING/MainProcess]   File "/home/yxguo/html/PokeVA/virtualenv/lib/python3.9/site-packages/celery/apps/beat.py", line 113, in start_scheduler
[2024-01-22 04:49:23,097: WARNING/MainProcess]     
[2024-01-22 04:49:23,097: WARNING/MainProcess] service.start()
[2024-01-22 04:49:23,097: WARNING/MainProcess]   File "/home/yxguo/html/PokeVA/virtualenv/lib/python3.9/site-packages/celery/beat.py", line 643, in start
[2024-01-22 04:49:23,098: WARNING/MainProcess]     
[2024-01-22 04:49:23,098: WARNING/MainProcess] interval = self.scheduler.tick()
[2024-01-22 04:49:23,098: WARNING/MainProcess]   File "/home/yxguo/html/PokeVA/virtualenv/lib/python3.9/site-packages/celery/beat.py", line 353, in tick
[2024-01-22 04:49:23,098: WARNING/MainProcess]     
[2024-01-22 04:49:23,098: WARNING/MainProcess] self.apply_entry(entry, producer=self.producer)
[2024-01-22 04:49:23,098: WARNING/MainProcess]   File "/home/yxguo/html/PokeVA/virtualenv/lib/python3.9/site-packages/kombu/utils/objects.py", line 40, in __get__
[2024-01-22 04:49:23,098: WARNING/MainProcess]     
[2024-01-22 04:49:23,098: WARNING/MainProcess] return super().__get__(instance, owner)
[2024-01-22 04:49:23,098: WARNING/MainProcess]   File "/home/yxguo/opt/lib/python3.9/functools.py", line 969, in __get__
[2024-01-22 04:49:23,098: WARNING/MainProcess]     
[2024-01-22 04:49:23,098: WARNING/MainProcess] val = self.func(instance)
[2024-01-22 04:49:23,098: WARNING/MainProcess]   File "/home/yxguo/html/PokeVA/virtualenv/lib/python3.9/site-packages/celery/beat.py", line 496, in producer
[2024-01-22 04:49:23,098: WARNING/MainProcess]     
[2024-01-22 04:49:23,099: WARNING/MainProcess] return self.Producer(self._ensure_connected(), auto_declare=False)
[2024-01-22 04:49:23,099: WARNING/MainProcess]   File "/home/yxguo/html/PokeVA/virtualenv/lib/python3.9/site-packages/celery/beat.py", line 479, in _ensure_connected
[2024-01-22 04:49:23,099: WARNING/MainProcess]     
[2024-01-22 04:49:23,099: WARNING/MainProcess] return self.connection.ensure_connection(
[2024-01-22 04:49:23,099: WARNING/MainProcess]   File "/home/yxguo/html/PokeVA/virtualenv/lib/python3.9/site-packages/kombu/connection.py", line 406, in ensure_connection
[2024-01-22 04:49:23,099: WARNING/MainProcess]     
[2024-01-22 04:49:23,099: WARNING/MainProcess] self._ensure_connection(*args, **kwargs)
[2024-01-22 04:49:23,099: WARNING/MainProcess]   File "/home/yxguo/html/PokeVA/virtualenv/lib/python3.9/site-packages/kombu/connection.py", line 459, in _ensure_connection
[2024-01-22 04:49:23,099: WARNING/MainProcess]     
[2024-01-22 04:49:23,099: WARNING/MainProcess] return retry_over_time(
[2024-01-22 04:49:23,099: WARNING/MainProcess]   File "/home/yxguo/opt/lib/python3.9/contextlib.py", line 135, in __exit__
[2024-01-22 04:49:23,099: WARNING/MainProcess]     
[2024-01-22 04:49:23,099: WARNING/MainProcess] self.gen.throw(type, value, traceback)
[2024-01-22 04:49:23,099: WARNING/MainProcess]   File "/home/yxguo/html/PokeVA/virtualenv/lib/python3.9/site-packages/kombu/connection.py", line 476, in _reraise_as_library_errors
[2024-01-22 04:49:23,099: WARNING/MainProcess]     
[2024-01-22 04:49:23,100: WARNING/MainProcess] raise ConnectionError(str(exc)) from exc
[2024-01-22 04:49:23,100: WARNING/MainProcess] kombu.exceptions
[2024-01-22 04:49:23,100: WARNING/MainProcess] .
[2024-01-22 04:49:23,100: WARNING/MainProcess] OperationalError
[2024-01-22 04:49:23,100: WARNING/MainProcess] : 
[2024-01-22 04:49:23,100: WARNING/MainProcess] [Errno 111] Connection refused
[2024-01-22 04:49:24,773: INFO/MainProcess] beat: Starting...
